Workbook
Name Actual_Points: OFFSET('Team Data'!$F$2,0,0,COUNTA('Team Data'!$F$2:$F$100032),1)
Name FPTS: OFFSET('Raw Data'!$K$2,0,0,COUNTA('Raw Data'!$A$2:$A$100001),1)
Name Ideal_Points: OFFSET('Team Data'!$E$2,0,0,COUNTA('Team Data'!$E$2:$E$100032),1)
Name Missed_Points: OFFSET('Team Data'!$G$2,0,0,COUNTA('Team Data'!$G$2:$G$100032),1)
Name ND_Starter_Points: OFFSET('Team Data'!$K$2,0,0,COUNTA('Team Data'!$K$2:$K$100032),1)
Name Non_Drafted_Player: OFFSET('Team Data'!$H$2,0,0,COUNTA('Team Data'!$H$2:$H$100032),1)
Name Player: OFFSET('Raw Data'!$G$2,0,0,COUNTA('Raw Data'!$A$2:$A$100001),1)
Name Pos: OFFSET('Raw Data'!$D$2,0,0,COUNTA('Raw Data'!$A$2:$A$100001),1)
Name Raw: OFFSET('Raw Data'!$A$2,0,0,COUNTA('Raw Data'!$A$2:$A$100001),11)
Name SLOT: OFFSET('Raw Data'!$F$2,0,0,COUNTA('Raw Data'!$A$2:$A$100001),1)
Name Team: OFFSET('Raw Data'!$B$2,0,0,COUNTA('Raw Data'!$A$2:$A$100001),1)
Name Team_Total: OFFSET('Team Data'!$A$2,0,0,COUNTA('Team Data'!$A$2:$A$100032),1)
Name Week: OFFSET('Raw Data'!$A$2,0,0,COUNTA('Raw Data'!$A$2:$A$100001),1)
Name Week_Total: OFFSET('Team Data'!$B$2,0,0,COUNTA('Team Data'!$B$2:$B$100032),1)

Sheet Raw Data
A1: Week | B1: Team Name | C1: Team/Pos | D1: Pos | E1: Team | F1: SLOT | G1: Player | H1: OPP | I1: STATUS | J1: Projected | K1: FPTS
A2: 1 | B2: Coach Carlt | C2: INDRB | D2: RB | E2: IND | F2: RB | G2: Jonathan Taylor | H2: Picken Dis Nose | I2: W 128.26-82.8 | J2: 16.27 | K2: 23.6
A3: 1 | B3: Coach Carlt | C3: LVTE | D3: TE | E3: LV | F3: Bench | G3: Brock Bowers | H3: Picken Dis Nose | I3: W 128.26-82.8 | J3: 0 | K3: 0
A4: 1 | B4: Coach Carlt | C4: NORB | D4: RB | E4: NO | F4: RB | G4: Travis Etienne Jr. | H4: Picken Dis Nose | I4: W 128.26-82.8 | J4: 13.5 | K4: 11.3
A5: 1 | B5: Coach Carlt | C5: CHIWR | D5: WR | E5: CHI | F5: WR | G5: Rome Odunze | H5: Picken Dis Nose | I5: W 128.26-82.8 | J5: 10.65 | K5: 6.2
A6: 1 | B6: Coach Carlt | C6: WSHQB | D6: QB | E6: WSH | F6: QB | G6: Jayden Daniels | H6: Picken Dis Nose | I6: W 128.26-82.8 | J6: 16.84 | K6: 17.66
A7: 1 | B7: Coach Carlt | C7: PITWR | D7: WR | E7: PIT | F7: WR | G7: Michael Pittman Jr. | H7: Picken Dis Nose | I7: W 128.26-82.8 | J7: 9.73 | K7: 7.3
A8: 1 | B8: Coach Carlt | C8: TENWR | D8: WR | E8: TEN | F8: FLEX | G8: Wan'Dale Robinson | H8: Picken Dis Nose | I8: W 128.26-82.8 | J8: 8.11 | K8: 6.3
A9: 1 | B9: Coach Carlt | C9: CHIRB | D9: RB | E9: CHI | F9: FLEX | G9: Kyle Monangai | H9: Picken Dis Nose | I9: W 128.26-82.8 | J9: 9.5 | K9: 19.4
A10: 1 | B10: Coach Carlt | C10: BUFWR | D10: WR | E10: BUF | F10: Bench | G10: Khalil Shakir | H10: Picken Dis Nose | I10: W 128.26-82.8 | J10: 7.45 | K10: 7
A11: 1 | B11: Coach Carlt | C11: TENRB | D11: RB | E11: TEN | F11: Bench | G11: Tyjae Spears | H11: Picken Dis Nose | I11: W 128.26-82.8 | J11: 7.93 | K11: 3.4
A12: 1 | B12: Coach Carlt | C12: PITD/ST | D12: D/ST | E12: PIT | F12: D/ST | G12: Steelers D/ST | H12: Picken Dis Nose | I12: W 128.26-82.8 | J12: 7.22 | K12: 19
A13: 1 | B13: Coach Carlt | C13: HOUQB | D13: QB | E13: HOU | F13: Bench | G13: C.J. Stroud | H13: Picken Dis Nose | I13: W 128.26-82.8 | J13: 16.23 | K13: 16.46
... A611: 3 | B611: Lemieuse-bouche sais quoi | C611: PITTE | D611: TE | E611: PIT | F611: TE | G611: Pat Freiermuth | H611: @Pleading the Fifth Down | I611: L 81.06-112.44 | J611: 6.44 | K611: 4.1

Sheet Team Data
A1: Team | B1: Week | C1: SLOT | D1: Pos Rank | E1: Ideal Points | F1: Actual Points | G1: Missed Points | H1: Drafted Player | I1: Starting Player | J1: Ideal Starting Player | K1: Points by Non-Drafted Starters
A2: Coach Carlt | B2: 1 | C2: QB | D2: 1 | E2: 17.66 | F2: 17.66 | G2: 0 | H2: 1 | I2: Jayden Daniels | J2: Jayden Daniels | K2: 0
A3: Coach Carlt | B3: 1 | C3: RB | D3: 1 | E3: 23.6 | F3: 23.6 | G3: 0 | H3: 1 | I3: Jonathan Taylor | J3: Jonathan Taylor | K3: 0
A4: Coach Carlt | B4: 1 | C4: RB | D4: 2 | E4: 19.4 | F4: 11.3 | G4: 8.1 | H4: 1 | I4: Travis Etienne Jr. | J4: Kyle Monangai | K4: 0
A5: Coach Carlt | B5: 1 | C5: WR | D5: 1 | E5: 7.3 | F5: 7.3 | G5: 0 | H5: 1 | I5: Michael Pittman Jr. | J5: Michael Pittman Jr. | K5: 0
A6: Coach Carlt | B6: 1 | C6: WR | D6: 2 | E6: 7 | F6: 6.2 | G6: 0.8 | H6: 1 | I6: Rome Odunze | J6: Khalil Shakir | K6: 0
A7: Coach Carlt | B7: 1 | C7: TE | D7: 1 | E7: 5.5 | F7: 5.5 | G7: 0 | H7: 1 | I7: Dalton Schultz | J7: Dalton Schultz | K7: 0
A8: Coach Carlt | B8: 1 | C8: FLEX | D8: 1 | E8: 11.3 | F8: 19.4 | G8: -8.1 | H8: 1 | I8: Kyle Monangai | J8: Travis Etienne Jr. | K8: 0
A9: Coach Carlt | B9: 1 | C9: FLEX | D9: 2 | E9: 6.3 | F9: 6.3 | G9: 0 | H9: 1 | I9: Wan'Dale Robinson | J9: Wan'Dale Robinson | K9: 0
A10: Coach Carlt | B10: 1 | C10: D/ST | D10: 1 | E10: 19 | F10: 19 | G10: 0 | H10: 1 | I10: Steelers D/ST | J10: Steelers D/ST | K10: 0
A11: Coach Carlt | B11: 1 | C11: K | D11: 1 | E11: 12 | F11: 12 | G11: 0 | H11: 1 | I11: Cairo Santos | J11: Cairo Santos | K11: 0
A12: Coach Carlt | B12: 2 | C12: QB | D12: 1 | E12: 17.02 | F12: 14.74 | G12: 2.28 | H12: 1 | I12: Jayden Daniels | J12: C.J. Stroud | K12: 0
A13: Coach Carlt | B13: 2 | C13: RB | D13: 1 | E13: 27.2 | F13: 27.2 | G13: 0 | H13: 1 | I13: Jonathan Taylor | J13: Jonathan Taylor | K13: 0
... A421: Jungle Drummer | B421: 3 | C421: K | D421: 1 | E421: 12 | F421: 12 | G421: 0 | H421: 0 | I421: Chase McLaughlin | J421: Chase McLaughlin | K421: 12

Sheet Team Summaries
A1: Team | B1: Week | C1: Ideal Points | D1: Actual Points | E1: Missed Points | F1: Non-Drafted Player | G1: Points by Non-Drafted Starters | J1: Averages by Team
A2: Coach Carlt | B2: 1 | C2: {=SUMIFS([0]!Ideal_Points,[0]!Team_Total,'Team Summaries'!A2,[0]!Week_Total,'Team Summaries'!B2)} -> 129.06 | D2: {=SUMIFS([0]!Actual_Points,[0]!Team_Total,'Team Summaries'!A2,[0]!Week_Total,'Team Summaries'!B2)} -> 128.26 | E2: {=SUMIFS([0]!Missed_Points,[0]!Team_Total,'Team Summaries'!A2,[0]!Week_Total,'Team Summaries'!B2)} -> 0.8 | F2: {=10-SUMIFS([0]!Non_Drafted_Player,[0]!Team_Total,'Team Summaries'!A2,[0]!Week_Total,'Team Summaries'!B2)} -> 0 | G2: {=SUMIFS([0]!ND_Starter_Points,[0]!Team_Total,'Team Summaries'!A2,[0]!Week_Total,'Team Summaries'!B2)} -> 0 | I2: Rank | J2: Team | K2: Possible Points | L2: Actual Points | M2: Points Missed | N2: Coaching Efficiency | O2: Undrafted Players | P2: Undrafted Points | Q2: Projection | R2: Projection_Starters | S2: Actual | T2: Byes | U2: Paced | V2: Dif | W2: INJ | X2: Weighted INJ | Y2: MoV | Z2: MoD | AA2: Opp Prop | AB2: Luck Rating | AC2: Manager Rating
A3: Picken Dis Nose | B3: 1 | C3: {=SUMIFS([0]!Ideal_Points,[0]!Team_Total,'Team Summaries'!A3,[0]!Week_Total,'Team Summaries'!B3)} -> 95.3 | D3: {=SUMIFS([0]!Actual_Points,[0]!Team_Total,'Team Summaries'!A3,[0]!Week_Total,'Team Summaries'!B3)} -> 82.8 | E3: {=SUMIFS([0]!Missed_Points,[0]!Team_Total,'Team Summaries'!A3,[0]!Week_Total,'Team Summaries'!B3)} -> 12.5 | F3: {=10-SUMIFS([0]!Non_Drafted_Player,[0]!Team_Total,'Team Summaries'!A3,[0]!Week_Total,'Team Summaries'!B3)} -> 2 | G3: {=SUMIFS([0]!ND_Starter_Points,[0]!Team_Total,'Team Summaries'!A3,[0]!Week_Total,'Team Summaries'!B3)} -> 20.2 | I3: 1 | J3: Coach Carlt | K3: =AVERAGEIF($A$2:$A$1000,J3,$C$2:$C$1000) -> 110.15333 | L3: =AVERAGEIF($A$2:$A$1000,Table1[[#This Row],[Team]],$D$2:$D$1000) -> 107.82667 | M3: =AVERAGEIF($A$2:$A$1000,Table1[[#This Row],[Team]],$E$2:$E$1000) -> 2.3266667 | N3: =Table1[[#This Row],[Actual Points]]/Table1[[#This Row],[Possible Points]] -> 0.97887793 | O3: =AVERAGEIF($A$2:$A$1000,Table1[[#This Row],[Team]],$F$2:$F$1000) -> 0 | P3: =AVERAGEIF($A$2:$A$1000,Table1[[#This Row],[Team]],$G$2:$G$1000) -> 0 | Q3: =_xlfn.XLOOKUP(Table1[[#This Row],[Team]],'Draft Recap'!$S$2:$S$15,'Draft Recap'!T$2:T$15) -> 2480 | R3: 1866 | S3: =_xlfn.XLOOKUP(Table1[[#This Row],[Team]],'Draft Recap'!$S$2:$S$15,'Draft Recap'!U$2:U$15) -> 376.86 | T3: =_xlfn.XLOOKUP(Table1[[#This Row],[Team]],'Draft Recap'!$S$2:$S$15,'Draft Recap'!V$2:V$15) -> 0 | U3: =_xlfn.XLOOKUP(Table1[[#This Row],[Team]],'Draft Recap'!$S$2:$S$15,'Draft Recap'!W$2:W$15) -> 2135.54 | V3: =_xlfn.XLOOKUP(Table1[[#This Row],[Team]],'Draft Recap'!$S$2:$S$15,'Draft Recap'!X$2:X$15) -> -344.46 | W3: =_xlfn.XLOOKUP(Table1[[#This Row],[Team]],'Draft Recap'!$S$2:$S$15,'Draft Recap'!Y$2:Y$15) -> 3 | X3: =_xlfn.XLOOKUP(Table1[[#This Row],[Team]],'Draft Recap'!$S$2:$S$15,'Draft Recap'!Z$2:Z$15) -> 9 | Y3: =_xlfn.XLOOKUP(Table1[[#This Row],[Team]],'Draft Recap'!$S$2:$S$15,'Draft Recap'!AA$2:AA$15) -> 25.153333 | Z3: =_xlfn.XLOOKUP(Table1[[#This Row],[Team]],'Draft Recap'!$S$2:$S$15,'Draft Recap'!AB$2:AB$15) -> 0 | AA3: =_xlfn.XLOOKUP(Table1[[#This Row],[Team]],'Draft Recap'!$S$2:$S$15,'Draft Recap'!AC$2:AC$15) -> 0.91511936 | AB3: =AVERAGE((Table1[[#This Row],[Dif]]-AVERAGE(Table1[Dif]))/STDEV(Table1[Dif]),-(Table1[[#This Row],[Weighted INJ]]-AVERAGE(Table1[Weighted INJ]))/STDEV(Table1[Weighted INJ]),-(Table1[[#This Row],[MoV]]-AVERAGE(Table1[MoV]))/STDEV(Table1[MoV]),(Table1[[#This Row],[MoD]]-AVERAGE(Table1[MoD]))/STDEV(Table1[MoD]),-(Table1[[#This Row],[Opp Prop]]-AVERAGE(Table1[Opp Prop]))/STDEV(Table1[Opp Prop])) -> -0.48406726 | AC3: =AVERAGE((Table1[[#This Row],[Coaching Efficiency]]-AVERAGE(Table1[Coaching Efficiency]))/STDEV(Table1[Coaching Efficiency]),(Table1[[#This Row],[Undrafted Points]]-AVERAGE(Table1[Undrafted Points]))/STDEV(Table1[Undrafted Points]),(Table1[[#This Row],[Projection_Starters]]-AVERAGE(Table1[Projection_Starters]))/STDEV(Table1[Projection_Starters])) -> 0.27953576
A4: The Strib Club | B4: 1 | C4: {=SUMIFS([0]!Ideal_Points,[0]!Team_Total,'Team Summaries'!A4,[0]!Week_Total,'Team Summaries'!B4)} -> 101.96 | D4: {=SUMIFS([0]!Actual_Points,[0]!Team_Total,'Team Summaries'!A4,[0]!Week_Total,'Team Summaries'!B4)} -> 88.46 | E4: {=SUMIFS([0]!Missed_Points,[0]!Team_Total,'Team Summaries'!A4,[0]!Week_Total,'Team Summaries'!B4)} -> 13.5 | F4: {=10-SUMIFS([0]!Non_Drafted_Player,[0]!Team_Total,'Team Summaries'!A4,[0]!Week_Total,'Team Summaries'!B4)} -> 0 | G4: {=SUMIFS([0]!ND_Starter_Points,[0]!Team_Total,'Team Summaries'!A4,[0]!Week_Total,'Team Summaries'!B4)} -> 0 | I4: =I3+1 -> 2 | J4: Picken Dis Nose | K4: =AVERAGEIF($A$2:$A$1000,J4,$C$2:$C$1000) -> 113.05333 | L4: =AVERAGEIF($A$2:$A$1000,Table1[[#This Row],[Team]],$D$2:$D$1000) -> 98.053333 | M4: =AVERAGEIF($A$2:$A$1000,Table1[[#This Row],[Team]],$E$2:$E$1000) -> 15 | N4: =Table1[[#This Row],[Actual Points]]/Table1[[#This Row],[Possible Points]] -> 0.86731926 | O4: =AVERAGEIF($A$2:$A$1000,Table1[[#This Row],[Team]],$F$2:$F$1000) -> 2.3333333 | P4: =AVERAGEIF($A$2:$A$1000,Table1[[#This Row],[Team]],$G$2:$G$1000) -> 12.666667 | Q4: =_xlfn.XLOOKUP(Table1[[#This Row],[Team]],'Draft Recap'!$S$2:$S$15,'Draft Recap'!T$2:T$15) -> 2339 | R4: 1839 | S4: =_xlfn.XLOOKUP(Table1[[#This Row],[Team]],'Draft Recap'!$S$2:$S$15,'Draft Recap'!U$2:U$15) -> 314.36 | T4: =_xlfn.XLOOKUP(Table1[[#This Row],[Team]],'Draft Recap'!$S$2:$S$15,'Draft Recap'!V$2:V$15) -> 0 | U4: =_xlfn.XLOOKUP(Table1[[#This Row],[Team]],'Draft Recap'!$S$2:$S$15,'Draft Recap'!W$2:W$15) -> 1781.3733 | V4: =_xlfn.XLOOKUP(Table1[[#This Row],[Team]],'Draft Recap'!$S$2:$S$15,'Draft Recap'!X$2:X$15) -> -557.62667 | W4: =_xlfn.XLOOKUP(Table1[[#This Row],[Team]],'Draft Recap'!$S$2:$S$15,'Draft Recap'!Y$2:Y$15) -> 5 | X4: =_xlfn.XLOOKUP(Table1[[#This Row],[Team]],'Draft Recap'!$S$2:$S$15,'Draft Recap'!Z$2:Z$15) -> 7.75 | Y4: =_xlfn.XLOOKUP(Table1[[#This Row],[Team]],'Draft Recap'!$S$2:$S$15,'Draft Recap'!AA$2:AA$15) -> 28.58 | Z4: =_xlfn.XLOOKUP(Table1[[#This Row],[Team]],'Draft Recap'!$S$2:$S$15,'Draft Recap'!AB$2:AB$15) -> 36.11 | AA4: =_xlfn.XLOOKUP(Table1[[#This Row],[Team]],'Draft Recap'!$S$2:$S$15,'Draft Recap'!AC$2:AC$15) -> 1 | AB4: =AVERAGE((Table1[[#This Row],[Dif]]-AVERAGE(Table1[Dif]))/STDEV(Table1[Dif]),-(Table1[[#This Row],[Weighted INJ]]-AVERAGE(Table1[Weighted INJ]))/STDEV(Table1[Weighted INJ]),-(Table1[[#This Row],[MoV]]-AVERAGE(Table1[MoV]))/STDEV(Table1[MoV]),(Table1[[#This Row],[MoD]]-AVERAGE(Table1[MoD]))/STDEV(Table1[MoD]),-(Table1[[#This Row],[Opp Prop]]-AVERAGE(Table1[Opp Prop]))/STDEV(Table1[Opp Prop])) -> -0.32022784 | AC4: =AVERAGE((Table1[[#This Row],[Coaching Efficiency]]-AVERAGE(Table1[Coaching Efficiency]))/STDEV(Table1[Coaching Efficiency]),(Table1[[#This Row],[Undrafted Points]]-AVERAGE(Table1[Undrafted Points]))/STDEV(Table1[Undrafted Points]),(Table1[[#This Row],[Projection_Starters]]-AVERAGE(Table1[Projection_Starters]))/STDEV(Table1[Projection_Starters])) -> 0.0045102441
A5: Shough and pray | B5: 1 | C5: {=SUMIFS([0]!Ideal_Points,[0]!Team_Total,'Team Summaries'!A5,[0]!Week_Total,'Team Summaries'!B5)} -> 164.2 | D5: {=SUMIFS([0]!Actual_Points,[0]!Team_Total,'Team Summaries'!A5,[0]!Week_Total,'Team Summaries'!B5)} -> 151.6 | E5: {=SUMIFS([0]!Missed_Points,[0]!Team_Total,'Team Summaries'!A5,[0]!Week_Total,'Team Summaries'!B5)} -> 12.6 | F5: {=10-SUMIFS([0]!Non_Drafted_Player,[0]!Team_Total,'Team Summaries'!A5,[0]!Week_Total,'Team Summaries'!B5)} -> 0 | G5: {=SUMIFS([0]!ND_Starter_Points,[0]!Team_Total,'Team Summaries'!A5,[0]!Week_Total,'Team Summaries'!B5)} -> 0 | I5: =I4+1 -> 3 | J5: The Strib Club | K5: =AVERAGEIF($A$2:$A$1000,J5,$C$2:$C$1000) -> 108.74667 | L5: =AVERAGEIF($A$2:$A$1000,Table1[[#This Row],[Team]],$D$2:$D$1000) -> 93.113333 | M5: =AVERAGEIF($A$2:$A$1000,Table1[[#This Row],[Team]],$E$2:$E$1000) -> 15.633333 | N5: =Table1[[#This Row],[Actual Points]]/Table1[[#This Row],[Possible Points]] -> 0.8562408 | O5: =AVERAGEIF($A$2:$A$1000,Table1[[#This Row],[Team]],$F$2:$F$1000) -> 1 | P5: =AVERAGEIF($A$2:$A$1000,Table1[[#This Row],[Team]],$G$2:$G$1000) -> 5.4333333 | Q5: =_xlfn.XLOOKUP(Table1[[#This Row],[Team]],'Draft Recap'!$S$2:$S$15,'Draft Recap'!T$2:T$15) -> 2163 | R5: 1807 | S5: =_xlfn.XLOOKUP(Table1[[#This Row],[Team]],'Draft Recap'!$S$2:$S$15,'Draft Recap'!U$2:U$15) -> 334.04 | T5: =_xlfn.XLOOKUP(Table1[[#This Row],[Team]],'Draft Recap'!$S$2:$S$15,'Draft Recap'!V$2:V$15) -> 0 | U5: =_xlfn.XLOOKUP(Table1[[#This Row],[Team]],'Draft Recap'!$S$2:$S$15,'Draft Recap'!W$2:W$15) -> 1786.2933 | V5: =_xlfn.XLOOKUP(Table1[[#This Row],[Team]],'Draft Recap'!$S$2:$S$15,'Draft Recap'!X$2:X$15) -> -376.70667 | W5: =_xlfn.XLOOKUP(Table1[[#This Row],[Team]],'Draft Recap'!$S$2:$S$15,'Draft Recap'!Y$2:Y$15) -> 4 | X5: =_xlfn.XLOOKUP(Table1[[#This Row],[Team]],'Draft Recap'!$S$2:$S$15,'Draft Recap'!Z$2:Z$15) -> 7 | Y5: =_xlfn.XLOOKUP(Table1[[#This Row],[Team]],'Draft Recap'!$S$2:$S$15,'Draft Recap'!AA$2:AA$15) -> 54.66 | Z5: =_xlfn.XLOOKUP(Table1[[#This Row],[Team]],'Draft Recap'!$S$2:$S$15,'Draft Recap'!AB$2:AB$15) -> 53.39 | AA5: =_xlfn.XLOOKUP(Table1[[#This Row],[Team]],'Draft Recap'!$S$2:$S$15,'Draft Recap'!AC$2:AC$15) -> 1.1144144 | AB5: =AVERAGE((Table1[[#This Row],[Dif]]-AVERAGE(Table1[Dif]))/STDEV(Table1[Dif]),-(Table1[[#This Row],[Weighted INJ]]-AVERAGE(Table1[Weighted INJ]))/STDEV(Table1[Weighted INJ]),-(Table1[[#This Row],[MoV]]-AVERAGE(Table1[MoV]))/STDEV(Table1[MoV]),(Table1[[#This Row],[MoD]]-AVERAGE(Table1[MoD]))/STDEV(Table1[MoD]),-(Table1[[#This Row],[Opp Prop]]-AVERAGE(Table1[Opp Prop]))/STDEV(Table1[Opp Prop])) -> -0.45155115 | AC5: =AVERAGE((Table1[[#This Row],[Coaching Efficiency]]-AVERAGE(Table1[Coaching Efficiency]))/STDEV(Table1[Coaching Efficiency]),(Table1[[#This Row],[Undrafted Points]]-AVERAGE(Table1[Undrafted Points]))/STDEV(Table1[Undrafted Points]),(Table1[[#This Row],[Projection_Starters]]-AVERAGE(Table1[Projection_Starters]))/STDEV(Table1[Projection_Starters])) -> -0.78267519
A6: Pleading the Fifth Down | B6: 1 | C6: {=SUMIFS([0]!Ideal_Points,[0]!Team_Total,'Team Summaries'!A6,[0]!Week_Total,'Team Summaries'!B6)} -> 145.84 | D6: {=SUMIFS([0]!Actual_Points,[0]!Team_Total,'Team Summaries'!A6,[0]!Week_Total,'Team Summaries'!B6)} -> 136.64 | E6: {=SUMIFS([0]!Missed_Points,[0]!Team_Total,'Team Summaries'!A6,[0]!Week_Total,'Team Summaries'!B6)} -> 9.2 | F6: {=10-SUMIFS([0]!Non_Drafted_Player,[0]!Team_Total,'Team Summaries'!A6,[0]!Week_Total,'Team Summaries'!B6)} -> 0 | G6: {=SUMIFS([0]!ND_Starter_Points,[0]!Team_Total,'Team Summaries'!A6,[0]!Week_Total,'Team Summaries'!B6)} -> 0 | I6: =I5+1 -> 4 | J6: Shough and pray | K6: =AVERAGEIF($A$2:$A$1000,J6,$C$2:$C$1000) -> 143.89333 | L6: =AVERAGEIF($A$2:$A$1000,Table1[[#This Row],[Team]],$D$2:$D$1000) -> 139.06 | M6: =AVERAGEIF($A$2:$A$1000,Table1[[#This Row],[Team]],$E$2:$E$1000) -> 4.8333333 | N6: =Table1[[#This Row],[Actual Points]]/Table1[[#This Row],[Possible Points]] -> 0.9664103 | O6: =AVERAGEIF($A$2:$A$1000,Table1[[#This Row],[Team]],$F$2:$F$1000) -> 1.3333333 | P6: =AVERAGEIF($A$2:$A$1000,Table1[[#This Row],[Team]],$G$2:$G$1000) -> 14.533333 | Q6: =_xlfn.XLOOKUP(Table1[[#This Row],[Team]],'Draft Recap'!$S$2:$S$15,'Draft Recap'!T$2:T$15) -> 2227 | R6: 1885 | S6: =_xlfn.XLOOKUP(Table1[[#This Row],[Team]],'Draft Recap'!$S$2:$S$15,'Draft Recap'!U$2:U$15) -> 447.88 | T6: =_xlfn.XLOOKUP(Table1[[#This Row],[Team]],'Draft Recap'!$S$2:$S$15,'Draft Recap'!V$2:V$15) -> 0 | U6: =_xlfn.XLOOKUP(Table1[[#This Row],[Team]],'Draft Recap'!$S$2:$S$15,'Draft Recap'!W$2:W$15) -> 2537.9867 | V6: =_xlfn.XLOOKUP(Table1[[#This Row],[Team]],'Draft Recap'!$S$2:$S$15,'Draft Recap'!X$2:X$15) -> 310.98667 | W6: =_xlfn.XLOOKUP(Table1[[#This Row],[Team]],'Draft Recap'!$S$2:$S$15,'Draft Recap'!Y$2:Y$15) -> 2 | X6: =_xlfn.XLOOKUP(Table1[[#This Row],[Team]],'Draft Recap'!$S$2:$S$15,'Draft Recap'!Z$2:Z$15) -> 4.25 | Y6: =_xlfn.XLOOKUP(Table1[[#This Row],[Team]],'Draft Recap'!$S$2:$S$15,'Draft Recap'!AA$2:AA$15) -> 36.08 | Z6: =_xlfn.XLOOKUP(Table1[[#This Row],[Team]],'Draft Recap'!$S$2:$S$15,'Draft Recap'!AB$2:AB$15) -> 0 | AA6: =_xlfn.XLOOKUP(Table1[[#This Row],[Team]],'Draft Recap'!$S$2:$S$15,'Draft Recap'!AC$2:AC$15) -> 1 | AB6: =AVERAGE((Table1[[#This Row],[Dif]]-AVERAGE(Table1[Dif]))/STDEV(Table1[Dif]),-(Table1[[#This Row],[Weighted INJ]]-AVERAGE(Table1[Weighted INJ]))/STDEV(Table1[Weighted INJ]),-(Table1[[#This Row],[MoV]]-AVERAGE(Table1[MoV]))/STDEV(Table1[MoV]),(Table1[[#This Row],[MoD]]-AVERAGE(Table1[MoD]))/STDEV(Table1[MoD]),-(Table1[[#This Row],[Opp Prop]]-AVERAGE(Table1[Opp Prop]))/STDEV(Table1[Opp Prop])) -> -0.00050644372 | AC6: =AVERAGE((Table1[[#This Row],[Coaching Efficiency]]-AVERAGE(Table1[Coaching Efficiency]))/STDEV(Table1[Coaching Efficiency]),(Table1[[#This Row],[Undrafted Points]]-AVERAGE(Table1[Undrafted Points]))/STDEV(Table1[Undrafted Points]),(Table1[[#This Row],[Projection_Starters]]-AVERAGE(Table1[Projection_Starters]))/STDEV(Table1[Projection_Starters])) -> 1.2190052
A7: Please Let Me Win IDK what 2 do | B7: 1 | C7: {=SUMIFS([0]!Ideal_Points,[0]!Team_Total,'Team Summaries'!A7,[0]!Week_Total,'Team Summaries'!B7)} -> 144.5 | D7: {=SUMIFS([0]!Actual_Points,[0]!Team_Total,'Team Summaries'!A7,[0]!Week_Total,'Team Summaries'!B7)} -> 144.5 | E7: {=SUMIFS([0]!Missed_Points,[0]!Team_Total,'Team Summaries'!A7,[0]!Week_Total,'Team Summaries'!B7)} -> 0 | F7: {=10-SUMIFS([0]!Non_Drafted_Player,[0]!Team_Total,'Team Summaries'!A7,[0]!Week_Total,'Team Summaries'!B7)} -> 0 | G7: {=SUMIFS([0]!ND_Starter_Points,[0]!Team_Total,'Team Summaries'!A7,[0]!Week_Total,'Team Summaries'!B7)} -> 0 | I7: =I6+1 -> 5 | J7: Pleading the Fifth Down | K7: =AVERAGEIF($A$2:$A$1000,J7,$C$2:$C$1000) -> 135.36667 | L7: =AVERAGEIF($A$2:$A$1000,Table1[[#This Row],[Team]],$D$2:$D$1000) -> 119.86667 | M7: =AVERAGEIF($A$2:$A$1000,Table1[[#This Row],[Team]],$E$2:$E$1000) -> 15.5 | N7: =Table1[[#This Row],[Actual Points]]/Table1[[#This Row],[Possible Points]] -> 0.88549618 | O7: =AVERAGEIF($A$2:$A$1000,Table1[[#This Row],[Team]],$F$2:$F$1000) -> 0.33333333 | P7: =AVERAGEIF($A$2:$A$1000,Table1[[#This Row],[Team]],$G$2:$G$1000) -> 4.5466667 | Q7: =_xlfn.XLOOKUP(Table1[[#This Row],[Team]],'Draft Recap'!$S$2:$S$15,'Draft Recap'!T$2:T$15) -> 2558 | R7: 1904 | S7: =_xlfn.XLOOKUP(Table1[[#This Row],[Team]],'Draft Recap'!$S$2:$S$15,'Draft Recap'!U$2:U$15) -> 455.04 | T7: =_xlfn.XLOOKUP(Table1[[#This Row],[Team]],'Draft Recap'!$S$2:$S$15,'Draft Recap'!V$2:V$15) -> 0 | U7: =_xlfn.XLOOKUP(Table1[[#This Row],[Team]],'Draft Recap'!$S$2:$S$15,'Draft Recap'!W$2:W$15) -> 2578.56 | V7: =_xlfn.XLOOKUP(Table1[[#This Row],[Team]],'Draft Recap'!$S$2:$S$15,'Draft Recap'!X$2:X$15) -> 20.56 | W7: =_xlfn.XLOOKUP(Table1[[#This Row],[Team]],'Draft Recap'!$S$2:$S$15,'Draft Recap'!Y$2:Y$15) -> 0 | X7: =_xlfn.XLOOKUP(Table1[[#This Row],[Team]],'Draft Recap'!$S$2:$S$15,'Draft Recap'!Z$2:Z$15) -> 0 | Y7: =_xlfn.XLOOKUP(Table1[[#This Row],[Team]],'Draft Recap'!$S$2:$S$15,'Draft Recap'!AA$2:AA$15) -> 16.92 | Z7: =_xlfn.XLOOKUP(Table1[[#This Row],[Team]],'Draft Recap'!$S$2:$S$15,'Draft Recap'!AB$2:AB$15) -> 7.86 | AA7: =_xlfn.XLOOKUP(Table1[[#This Row],[Team]],'Draft Recap'!$S$2:$S$15,'Draft Recap'!AC$2:AC$15) -> 1 | AB7: =AVERAGE((Table1[[#This Row],[Dif]]-AVERAGE(Table1[Dif]))/STDEV(Table1[Dif]),-(Table1[[#This Row],[Weighted INJ]]-AVERAGE(Table1[Weighted INJ]))/STDEV(Table1[Weighted INJ]),-(Table1[[#This Row],[MoV]]-AVERAGE(Table1[MoV]))/STDEV(Table1[MoV]),(Table1[[#This Row],[MoD]]-AVERAGE(Table1[MoD]))/STDEV(Table1[MoD]),-(Table1[[#This Row],[Opp Prop]]-AVERAGE(Table1[Opp Prop]))/STDEV(Table1[Opp Prop])) -> 0.34517239 | AC7: =AVERAGE((Table1[[#This Row],[Coaching Efficiency]]-AVERAGE(Table1[Coaching Efficiency]))/STDEV(Table1[Coaching Efficiency]),(Table1[[#This Row],[Undrafted Points]]-AVERAGE(Table1[Undrafted Points]))/STDEV(Table1[Undrafted Points]),(Table1[[#This Row],[Projection_Starters]]-AVERAGE(Table1[Projection_Starters]))/STDEV(Table1[Projection_Starters])) -> 0.22068711
A8: I'm At My Limit | B8: 1 | C8: {=SUMIFS([0]!Ideal_Points,[0]!Team_Total,'Team Summaries'!A8,[0]!Week_Total,'Team Summaries'!B8)} -> 111 | D8: {=SUMIFS([0]!Actual_Points,[0]!Team_Total,'Team Summaries'!A8,[0]!Week_Total,'Team Summaries'!B8)} -> 111 | E8: {=SUMIFS([0]!Missed_Points,[0]!Team_Total,'Team Summaries'!A8,[0]!Week_Total,'Team Summaries'!B8)} -> 0 | F8: {=10-SUMIFS([0]!Non_Drafted_Player,[0]!Team_Total,'Team Summaries'!A8,[0]!Week_Total,'Team Summaries'!B8)} -> 1 | G8: {=SUMIFS([0]!ND_Starter_Points,[0]!Team_Total,'Team Summaries'!A8,[0]!Week_Total,'Team Summaries'!B8)} -> 7 | I8: =I7+1 -> 6 | J8: Please Let Me Win IDK what 2 do | K8: =AVERAGEIF($A$2:$A$1000,J8,$C$2:$C$1000) -> 140.96 | L8: =AVERAGEIF($A$2:$A$1000,Table1[[#This Row],[Team]],$D$2:$D$1000) -> 136.39333 | M8: =AVERAGEIF($A$2:$A$1000,Table1[[#This Row],[Team]],$E$2:$E$1000) -> 4.5666667 | N8: =Table1[[#This Row],[Actual Points]]/Table1[[#This Row],[Possible Points]] -> 0.9676031 | O8: =AVERAGEIF($A$2:$A$1000,Table1[[#This Row],[Team]],$F$2:$F$1000) -> 0.33333333 | P8: =AVERAGEIF($A$2:$A$1000,Table1[[#This Row],[Team]],$G$2:$G$1000) -> 7.4066667 | Q8: =_xlfn.XLOOKUP(Table1[[#This Row],[Team]],'Draft Recap'!$S$2:$S$15,'Draft Recap'!T$2:T$15) -> 2178 | R8: 1881 | S8: =_xlfn.XLOOKUP(Table1[[#This Row],[Team]],'Draft Recap'!$S$2:$S$15,'Draft Recap'!U$2:U$15) -> 414.46 | T8: =_xlfn.XLOOKUP(Table1[[#This Row],[Team]],'Draft Recap'!$S$2:$S$15,'Draft Recap'!V$2:V$15) -> 0 | U8: =_xlfn.XLOOKUP(Table1[[#This Row],[Team]],'Draft Recap'!$S$2:$S$15,'Draft Recap'!W$2:W$15) -> 2348.6067 | V8: =_xlfn.XLOOKUP(Table1[[#This Row],[Team]],'Draft Recap'!$S$2:$S$15,'Draft Recap'!X$2:X$15) -> 170.60667 | W8: =_xlfn.XLOOKUP(Table1[[#This Row],[Team]],'Draft Recap'!$S$2:$S$15,'Draft Recap'!Y$2:Y$15) -> 1 | X8: =_xlfn.XLOOKUP(Table1[[#This Row],[Team]],'Draft Recap'!$S$2:$S$15,'Draft Recap'!Z$2:Z$15) -> 2 | Y8: =_xlfn.XLOOKUP(Table1[[#This Row],[Team]],'Draft Recap'!$S$2:$S$15,'Draft Recap'!AA$2:AA$15) -> 22.36 | Z8: =_xlfn.XLOOKUP(Table1[[#This Row],[Team]],'Draft Recap'!$S$2:$S$15,'Draft Recap'!AB$2:AB$15) -> 22.08 | AA8: =_xlfn.XLOOKUP(Table1[[#This Row],[Team]],'Draft Recap'!$S$2:$S$15,'Draft Recap'!AC$2:AC$15) -> 1.0616324 | AB8: =AVERAGE((Table1[[#This Row],[Dif]]-AVERAGE(Table1[Dif]))/STDEV(Table1[Dif]),-(Table1[[#This Row],[Weighted INJ]]-AVERAGE(Table1[Weighted INJ]))/STDEV(Table1[Weighted INJ]),-(Table1[[#This Row],[MoV]]-AVERAGE(Table1[MoV]))/STDEV(Table1[MoV]),(Table1[[#This Row],[MoD]]-AVERAGE(Table1[MoD]))/STDEV(Table1[MoD]),-(Table1[[#This Row],[Opp Prop]]-AVERAGE(Table1[Opp Prop]))/STDEV(Table1[Opp Prop])) -> 0.34958323 | AC8: =AVERAGE((Table1[[#This Row],[Coaching Efficiency]]-AVERAGE(Table1[Coaching Efficiency]))/STDEV(Table1[Coaching Efficiency]),(Table1[[#This Row],[Undrafted Points]]-AVERAGE(Table1[Undrafted Points]))/STDEV(Table1[Undrafted Points]),(Table1[[#This Row],[Projection_Starters]]-AVERAGE(Table1[Projection_Starters]))/STDEV(Table1[Projection_Starters])) -> 0.77002374
A9: Puka bit my finger | B9: 1 | C9: {=SUMIFS([0]!Ideal_Points,[0]!Team_Total,'Team Summaries'!A9,[0]!Week_Total,'Team Summaries'!B9)} -> 115.04 | D9: {=SUMIFS([0]!Actual_Points,[0]!Team_Total,'Team Summaries'!A9,[0]!Week_Total,'Team Summaries'!B9)} -> 80.56 | E9: {=SUMIFS([0]!Missed_Points,[0]!Team_Total,'Team Summaries'!A9,[0]!Week_Total,'Team Summaries'!B9)} -> 34.48 | F9: {=10-SUMIFS([0]!Non_Drafted_Player,[0]!Team_Total,'Team Summaries'!A9,[0]!Week_Total,'Team Summaries'!B9)} -> 0 | G9: {=SUMIFS([0]!ND_Starter_Points,[0]!Team_Total,'Team Summaries'!A9,[0]!Week_Total,'Team Summaries'!B9)} -> 0 | I9: =I8+1 -> 7 | J9: I'm At My Limit | K9: =AVERAGEIF($A$2:$A$1000,J9,$C$2:$C$1000) -> 124.28 | L9: =AVERAGEIF($A$2:$A$1000,Table1[[#This Row],[Team]],$D$2:$D$1000) -> 110.16 | M9: =AVERAGEIF($A$2:$A$1000,Table1[[#This Row],[Team]],$E$2:$E$1000) -> 14.12 | N9: =Table1[[#This Row],[Actual Points]]/Table1[[#This Row],[Possible Points]] -> 0.88638558 | O9: =AVERAGEIF($A$2:$A$1000,Table1[[#This Row],[Team]],$F$2:$F$1000) -> 1.3333333 | P9: =AVERAGEIF($A$2:$A$1000,Table1[[#This Row],[Team]],$G$2:$G$1000) -> 13.333333 | Q9: =_xlfn.XLOOKUP(Table1[[#This Row],[Team]],'Draft Recap'!$S$2:$S$15,'Draft Recap'!T$2:T$15) -> 2425 | R9: 1874 | S9: =_xlfn.XLOOKUP(Table1[[#This Row],[Team]],'Draft Recap'!$S$2:$S$15,'Draft Recap'!U$2:U$15) -> 398.46 | T9: =_xlfn.XLOOKUP(Table1[[#This Row],[Team]],'Draft Recap'!$S$2:$S$15,'Draft Recap'!V$2:V$15) -> 0 | U9: =_xlfn.XLOOKUP(Table1[[#This Row],[Team]],'Draft Recap'!$S$2:$S$15,'Draft Recap'!W$2:W$15) -> 2257.94 | V9: =_xlfn.XLOOKUP(Table1[[#This Row],[Team]],'Draft Recap'!$S$2:$S$15,'Draft Recap'!X$2:X$15) -> -167.06 | W9: =_xlfn.XLOOKUP(Table1[[#This Row],[Team]],'Draft Recap'!$S$2:$S$15,'Draft Recap'!Y$2:Y$15) -> 2 | X9: =_xlfn.XLOOKUP(Table1[[#This Row],[Team]],'Draft Recap'!$S$2:$S$15,'Draft Recap'!Z$2:Z$15) -> 1.25 | Y9: =_xlfn.XLOOKUP(Table1[[#This Row],[Team]],'Draft Recap'!$S$2:$S$15,'Draft Recap'!AA$2:AA$15) -> 37.04 | Z9: =_xlfn.XLOOKUP(Table1[[#This Row],[Team]],'Draft Recap'!$S$2:$S$15,'Draft Recap'!AB$2:AB$15) -> 35.5 | AA9: =_xlfn.XLOOKUP(Table1[[#This Row],[Team]],'Draft Recap'!$S$2:$S$15,'Draft Recap'!AC$2:AC$15) -> 1 | AB9: =AVERAGE((Table1[[#This Row],[Dif]]-AVERAGE(Table1[Dif]))/STDEV(Table1[Dif]),-(Table1[[#This Row],[Weighted INJ]]-AVERAGE(Table1[Weighted INJ]))/STDEV(Table1[Weighted INJ]),-(Table1[[#This Row],[MoV]]-AVERAGE(Table1[MoV]))/STDEV(Table1[MoV]),(Table1[[#This Row],[MoD]]-AVERAGE(Table1[MoD]))/STDEV(Table1[MoD]),-(Table1[[#This Row],[Opp Prop]]-AVERAGE(Table1[Opp Prop]))/STDEV(Table1[Opp Prop])) -> 0.23853729 | AC9: =AVERAGE((Table1[[#This Row],[Coaching Efficiency]]-AVERAGE(Table1[Coaching Efficiency]))/STDEV(Table1[Coaching Efficiency]),(Table1[[#This Row],[Undrafted Points]]-AVERAGE(Table1[Undrafted Points]))/STDEV(Table1[Undrafted Points]),(Table1[[#This Row],[Projection_Starters]]-AVERAGE(Table1[Projection_Starters]))/STDEV(Table1[Projection_Starters])) -> 0.48525626
A10: Lemieuse-bouche sais quoi | B10: 1 | C10: {=SUMIFS([0]!Ideal_Points,[0]!Team_Total,'Team Summaries'!A10,[0]!Week_Total,'Team Summaries'!B10)} -> 128.52 | D10: {=SUMIFS([0]!Actual_Points,[0]!Team_Total,'Team Summaries'!A10,[0]!Week_Total,'Team Summaries'!B10)} -> 122.52 | E10: {=SUMIFS([0]!Missed_Points,[0]!Team_Total,'Team Summaries'!A10,[0]!Week_Total,'Team Summaries'!B10)} -> 6 | F10: {=10-SUMIFS([0]!Non_Drafted_Player,[0]!Team_Total,'Team Summaries'!A10,[0]!Week_Total,'Team Summaries'!B10)} -> 0 | G10: {=SUMIFS([0]!ND_Starter_Points,[0]!Team_Total,'Team Summaries'!A10,[0]!Week_Total,'Team Summaries'!B10)} -> 0 | I10: =I9+1 -> 8 | J10: Puka bit my finger | K10: =AVERAGEIF($A$2:$A$1000,J10,$C$2:$C$1000) -> 115.66667 | L10: =AVERAGEIF($A$2:$A$1000,Table1[[#This Row],[Team]],$D$2:$D$1000) -> 96.473333 | M10: =AVERAGEIF($A$2:$A$1000,Table1[[#This Row],[Team]],$E$2:$E$1000) -> 19.193333 | N10: =Table1[[#This Row],[Actual Points]]/Table1[[#This Row],[Possible Points]] -> 0.8340634 | O10: =AVERAGEIF($A$2:$A$1000,Table1[[#This Row],[Team]],$F$2:$F$1000) -> 0 | P10: =AVERAGEIF($A$2:$A$1000,Table1[[#This Row],[Team]],$G$2:$G$1000) -> 0 | Q10: =_xlfn.XLOOKUP(Table1[[#This Row],[Team]],'Draft Recap'!$S$2:$S$15,'Draft Recap'!T$2:T$15) -> 2523 | R10: 1875 | S10: =_xlfn.XLOOKUP(Table1[[#This Row],[Team]],'Draft Recap'!$S$2:$S$15,'Draft Recap'!U$2:U$15) -> 419.8 | T10: =_xlfn.XLOOKUP(Table1[[#This Row],[Team]],'Draft Recap'!$S$2:$S$15,'Draft Recap'!V$2:V$15) -> 0 | U10: =_xlfn.XLOOKUP(Table1[[#This Row],[Team]],'Draft Recap'!$S$2:$S$15,'Draft Recap'!W$2:W$15) -> 2378.8667 | V10: =_xlfn.XLOOKUP(Table1[[#This Row],[Team]],'Draft Recap'!$S$2:$S$15,'Draft Recap'!X$2:X$15) -> -144.13333 | W10: =_xlfn.XLOOKUP(Table1[[#This Row],[Team]],'Draft Recap'!$S$2:$S$15,'Draft Recap'!Y$2:Y$15) -> 2 | X10: =_xlfn.XLOOKUP(Table1[[#This Row],[Team]],'Draft Recap'!$S$2:$S$15,'Draft Recap'!Z$2:Z$15) -> 7 | Y10: =_xlfn.XLOOKUP(Table1[[#This Row],[Team]],'Draft Recap'!$S$2:$S$15,'Draft Recap'!AA$2:AA$15) -> 34.44 | Z10: =_xlfn.XLOOKUP(Table1[[#This Row],[Team]],'Draft Recap'!$S$2:$S$15,'Draft Recap'!AB$2:AB$15) -> 26.45 | AA10: =_xlfn.XLOOKUP(Table1[[#This Row],[Team]],'Draft Recap'!$S$2:$S$15,'Draft Recap'!AC$2:AC$15) -> 1 | AB10: =AVERAGE((Table1[[#This Row],[Dif]]-AVERAGE(Table1[Dif]))/STDEV(Table1[Dif]),-(Table1[[#This Row],[Weighted INJ]]-AVERAGE(Table1[Weighted INJ]))/STDEV(Table1[Weighted INJ]),-(Table1[[#This Row],[MoV]]-AVERAGE(Table1[MoV]))/STDEV(Table1[MoV]),(Table1[[#This Row],[MoD]]-AVERAGE(Table1[MoD]))/STDEV(Table1[MoD]),-(Table1[[#This Row],[Opp Prop]]-AVERAGE(Table1[Opp Prop]))/STDEV(Table1[Opp Prop])) -> -0.15023748 | AC10: =AVERAGE((Table1[[#This Row],[Coaching Efficiency]]-AVERAGE(Table1[Coaching Efficiency]))/STDEV(Table1[Coaching Efficiency]),(Table1[[#This Row],[Undrafted Points]]-AVERAGE(Table1[Undrafted Points]))/STDEV(Table1[Undrafted Points]),(Table1[[#This Row],[Projection_Starters]]-AVERAGE(Table1[Projection_Starters]))/STDEV(Table1[Projection_Starters])) -> -0.66659724
A11: the medical tent apparently | B11: 1 | C11: {=SUMIFS([0]!Ideal_Points,[0]!Team_Total,'Team Summaries'!A11,[0]!Week_Total,'Team Summaries'!B11)} -> 92.76 | D11: {=SUMIFS([0]!Actual_Points,[0]!Team_Total,'Team Summaries'!A11,[0]!Week_Total,'Team Summaries'!B11)} -> 87.26 | E11: {=SUMIFS([0]!Missed_Points,[0]!Team_Total,'Team Summaries'!A11,[0]!Week_Total,'Team Summaries'!B11)} -> 5.5 | F11: {=10-SUMIFS([0]!Non_Drafted_Player,[0]!Team_Total,'Team Summaries'!A11,[0]!Week_Total,'Team Summaries'!B11)} -> 0 | G11: {=SUMIFS([0]!ND_Starter_Points,[0]!Team_Total,'Team Summaries'!A11,[0]!Week_Total,'Team Summaries'!B11)} -> 0 | I11: =I10+1 -> 9 | J11: Lemieuse-bouche sais quoi | K11: =AVERAGEIF($A$2:$A$1000,J11,$C$2:$C$1000) -> 111.16667 | L11: =AVERAGEIF($A$2:$A$1000,Table1[[#This Row],[Team]],$D$2:$D$1000) -> 106.83333 | M11: =AVERAGEIF($A$2:$A$1000,Table1[[#This Row],[Team]],$E$2:$E$1000) -> 4.3333333 | N11: =Table1[[#This Row],[Actual Points]]/Table1[[#This Row],[Possible Points]] -> 0.96101949 | O11: =AVERAGEIF($A$2:$A$1000,Table1[[#This Row],[Team]],$F$2:$F$1000) -> 0.66666667 | P11: =AVERAGEIF($A$2:$A$1000,Table1[[#This Row],[Team]],$G$2:$G$1000) -> 3.7 | Q11: =_xlfn.XLOOKUP(Table1[[#This Row],[Team]],'Draft Recap'!$S$2:$S$15,'Draft Recap'!T$2:T$15) -> 2298 | R11: 1859 | S11: =_xlfn.XLOOKUP(Table1[[#This Row],[Team]],'Draft Recap'!$S$2:$S$15,'Draft Recap'!U$2:U$15) -> 352.8 | T11: =_xlfn.XLOOKUP(Table1[[#This Row],[Team]],'Draft Recap'!$S$2:$S$15,'Draft Recap'!V$2:V$15) -> 0 | U11: =_xlfn.XLOOKUP(Table1[[#This Row],[Team]],'Draft Recap'!$S$2:$S$15,'Draft Recap'!W$2:W$15) -> 1999.2 | V11: =_xlfn.XLOOKUP(Table1[[#This Row],[Team]],'Draft Recap'!$S$2:$S$15,'Draft Recap'!X$2:X$15) -> -298.8 | W11: =_xlfn.XLOOKUP(Table1[[#This Row],[Team]],'Draft Recap'!$S$2:$S$15,'Draft Recap'!Y$2:Y$15) -> 1 | X11: =_xlfn.XLOOKUP(Table1[[#This Row],[Team]],'Draft Recap'!$S$2:$S$15,'Draft Recap'!Z$2:Z$15) -> 2 | Y11: =_xlfn.XLOOKUP(Table1[[#This Row],[Team]],'Draft Recap'!$S$2:$S$15,'Draft Recap'!AA$2:AA$15) -> 29.78 | Z11: =_xlfn.XLOOKUP(Table1[[#This Row],[Team]],'Draft Recap'!$S$2:$S$15,'Draft Recap'!AB$2:AB$15) -> 31.38 | AA11: =_xlfn.XLOOKUP(Table1[[#This Row],[Team]],'Draft Recap'!$S$2:$S$15,'Draft Recap'!AC$2:AC$15) -> 0.94539545 | AB11: =AVERAGE((Table1[[#This Row],[Dif]]-AVERAGE(Table1[Dif]))/STDEV(Table1[Dif]),-(Table1[[#This Row],[Weighted INJ]]-AVERAGE(Table1[Weighted INJ]))/STDEV(Table1[Weighted INJ]),-(Table1[[#This Row],[MoV]]-AVERAGE(Table1[MoV]))/STDEV(Table1[MoV]),(Table1[[#This Row],[MoD]]-AVERAGE(Table1[MoD]))/STDEV(Table1[MoD]),-(Table1[[#This Row],[Opp Prop]]-AVERAGE(Table1[Opp Prop]))/STDEV(Table1[Opp Prop])) -> 0.23349576 | AC11: =AVERAGE((Table1[[#This Row],[Coaching Efficiency]]-AVERAGE(Table1[Coaching Efficiency]))/STDEV(Table1[Coaching Efficiency]),(Table1[[#This Row],[Undrafted Points]]-AVERAGE(Table1[Undrafted Points]))/STDEV(Table1[Undrafted Points]),(Table1[[#This Row],[Projection_Starters]]-AVERAGE(Table1[Projection_Starters]))/STDEV(Table1[Projection_Starters])) -> 0.3111977
A12: your friendly fantasy despot | B12: 1 | C12: {=SUMIFS([0]!Ideal_Points,[0]!Team_Total,'Team Summaries'!A12,[0]!Week_Total,'Team Summaries'!B12)} -> 151.06 | D12: {=SUMIFS([0]!Actual_Points,[0]!Team_Total,'Team Summaries'!A12,[0]!Week_Total,'Team Summaries'!B12)} -> 137.48 | E12: {=SUMIFS([0]!Missed_Points,[0]!Team_Total,'Team Summaries'!A12,[0]!Week_Total,'Team Summaries'!B12)} -> 13.58 | F12: {=10-SUMIFS([0]!Non_Drafted_Player,[0]!Team_Total,'Team Summaries'!A12,[0]!Week_Total,'Team Summaries'!B12)} -> 0 | G12: {=SUMIFS([0]!ND_Starter_Points,[0]!Team_Total,'Team Summaries'!A12,[0]!Week_Total,'Team Summaries'!B12)} -> 0 | I12: =I11+1 -> 10 | J12: the medical tent apparently | K12: =AVERAGEIF($A$2:$A$1000,J12,$C$2:$C$1000) -> 102.68667 | L12: =AVERAGEIF($A$2:$A$1000,Table1[[#This Row],[Team]],$D$2:$D$1000) -> 91.466667 | M12: =AVERAGEIF($A$2:$A$1000,Table1[[#This Row],[Team]],$E$2:$E$1000) -> 11.22 | N12: =Table1[[#This Row],[Actual Points]]/Table1[[#This Row],[Possible Points]] -> 0.89073557 | O12: =AVERAGEIF($A$2:$A$1000,Table1[[#This Row],[Team]],$F$2:$F$1000) -> 0 | P12: =AVERAGEIF($A$2:$A$1000,Table1[[#This Row],[Team]],$G$2:$G$1000) -> 0 | Q12: =_xlfn.XLOOKUP(Table1[[#This Row],[Team]],'Draft Recap'!$S$2:$S$15,'Draft Recap'!T$2:T$15) -> 2433 | R12: 1830 | S12: =_xlfn.XLOOKUP(Table1[[#This Row],[Team]],'Draft Recap'!$S$2:$S$15,'Draft Recap'!U$2:U$15) -> 364.4 | T12: =_xlfn.XLOOKUP(Table1[[#This Row],[Team]],'Draft Recap'!$S$2:$S$15,'Draft Recap'!V$2:V$15) -> 0 | U12: =_xlfn.XLOOKUP(Table1[[#This Row],[Team]],'Draft Recap'!$S$2:$S$15,'Draft Recap'!W$2:W$15) -> 2064.9333 | V12: =_xlfn.XLOOKUP(Table1[[#This Row],[Team]],'Draft Recap'!$S$2:$S$15,'Draft Recap'!X$2:X$15) -> -368.06667 | W12: =_xlfn.XLOOKUP(Table1[[#This Row],[Team]],'Draft Recap'!$S$2:$S$15,'Draft Recap'!Y$2:Y$15) -> 0 | X12: =_xlfn.XLOOKUP(Table1[[#This Row],[Team]],'Draft Recap'!$S$2:$S$15,'Draft Recap'!Z$2:Z$15) -> 0 | Y12: =_xlfn.XLOOKUP(Table1[[#This Row],[Team]],'Draft Recap'!$S$2:$S$15,'Draft Recap'!AA$2:AA$15) -> 0 | Z12: =_xlfn.XLOOKUP(Table1[[#This Row],[Team]],'Draft Recap'!$S$2:$S$15,'Draft Recap'!AB$2:AB$15) -> 32.76 | AA12: =_xlfn.XLOOKUP(Table1[[#This Row],[Team]],'Draft Recap'!$S$2:$S$15,'Draft Recap'!AC$2:AC$15) -> 1.3359859 | AB12: =AVERAGE((Table1[[#This Row],[Dif]]-AVERAGE(Table1[Dif]))/STDEV(Table1[Dif]),-(Table1[[#This Row],[Weighted INJ]]-AVERAGE(Table1[Weighted INJ]))/STDEV(Table1[Weighted INJ]),-(Table1[[#This Row],[MoV]]-AVERAGE(Table1[MoV]))/STDEV(Table1[MoV]),(Table1[[#This Row],[MoD]]-AVERAGE(Table1[MoD]))/STDEV(Table1[MoD]),-(Table1[[#This Row],[Opp Prop]]-AVERAGE(Table1[Opp Prop]))/STDEV(Table1[Opp Prop])) -> -0.075371635 | AC12: =AVERAGE((Table1[[#This Row],[Coaching Efficiency]]-AVERAGE(Table1[Coaching Efficiency]))/STDEV(Table1[Coaching Efficiency]),(Table1[[#This Row],[Undrafted Points]]-AVERAGE(Table1[Undrafted Points]))/STDEV(Table1[Undrafted Points]),(Table1[[#This Row],[Projection_Starters]]-AVERAGE(Table1[Projection_Starters]))/STDEV(Table1[Projection_Starters])) -> -0.65931716
A13: pretty good team | B13: 1 | C13: {=SUMIFS([0]!Ideal_Points,[0]!Team_Total,'Team Summaries'!A13,[0]!Week_Total,'Team Summaries'!B13)} -> 128.9 | D13: {=SUMIFS([0]!Actual_Points,[0]!Team_Total,'Team Summaries'!A13,[0]!Week_Total,'Team Summaries'!B13)} -> 110.4 | E13: {=SUMIFS([0]!Missed_Points,[0]!Team_Total,'Team Summaries'!A13,[0]!Week_Total,'Team Summaries'!B13)} -> 18.5 | F13: {=10-SUMIFS([0]!Non_Drafted_Player,[0]!Team_Total,'Team Summaries'!A13,[0]!Week_Total,'Team Summaries'!B13)} -> 0 | G13: {=SUMIFS([0]!ND_Starter_Points,[0]!Team_Total,'Team Summaries'!A13,[0]!Week_Total,'Team Summaries'!B13)} -> 0 | I13: =I12+1 -> 11 | J13: your friendly fantasy despot | K13: =AVERAGEIF($A$2:$A$1000,J13,$C$2:$C$1000) -> 123.50667 | L13: =AVERAGEIF($A$2:$A$1000,Table1[[#This Row],[Team]],$D$2:$D$1000) -> 118.13333 | M13: =AVERAGEIF($A$2:$A$1000,Table1[[#This Row],[Team]],$E$2:$E$1000) -> 5.3733333 | N13: =Table1[[#This Row],[Actual Points]]/Table1[[#This Row],[Possible Points]] -> 0.95649358 | O13: =AVERAGEIF($A$2:$A$1000,Table1[[#This Row],[Team]],$F$2:$F$1000) -> 0.33333333 | P13: =AVERAGEIF($A$2:$A$1000,Table1[[#This Row],[Team]],$G$2:$G$1000) -> 0.33333333 | Q13: =_xlfn.XLOOKUP(Table1[[#This Row],[Team]],'Draft Recap'!$S$2:$S$15,'Draft Recap'!T$2:T$15) -> 2486 | R13: 1791 | S13: =_xlfn.XLOOKUP(Table1[[#This Row],[Team]],'Draft Recap'!$S$2:$S$15,'Draft Recap'!U$2:U$15) -> 438.14 | T13: =_xlfn.XLOOKUP(Table1[[#This Row],[Team]],'Draft Recap'!$S$2:$S$15,'Draft Recap'!V$2:V$15) -> 0 | U13: =_xlfn.XLOOKUP(Table1[[#This Row],[Team]],'Draft Recap'!$S$2:$S$15,'Draft Recap'!W$2:W$15) -> 2482.7933 | V13: =_xlfn.XLOOKUP(Table1[[#This Row],[Team]],'Draft Recap'!$S$2:$S$15,'Draft Recap'!X$2:X$15) -> -3.2066667 | W13: =_xlfn.XLOOKUP(Table1[[#This Row],[Team]],'Draft Recap'!$S$2:$S$15,'Draft Recap'!Y$2:Y$15) -> 3 | X13: =_xlfn.XLOOKUP(Table1[[#This Row],[Team]],'Draft Recap'!$S$2:$S$15,'Draft Recap'!Z$2:Z$15) -> 8.75 | Y13: =_xlfn.XLOOKUP(Table1[[#This Row],[Team]],'Draft Recap'!$S$2:$S$15,'Draft Recap'!AA$2:AA$15) -> 31.29 | Z13: =_xlfn.XLOOKUP(Table1[[#This Row],[Team]],'Draft Recap'!$S$2:$S$15,'Draft Recap'!AB$2:AB$15) -> 7.54 | AA13: =_xlfn.XLOOKUP(Table1[[#This Row],[Team]],'Draft Recap'!$S$2:$S$15,'Draft Recap'!AC$2:AC$15) -> 0.91317131 | AB13: =AVERAGE((Table1[[#This Row],[Dif]]-AVERAGE(Table1[Dif]))/STDEV(Table1[Dif]),-(Table1[[#This Row],[Weighted INJ]]-AVERAGE(Table1[Weighted INJ]))/STDEV(Table1[Weighted INJ]),-(Table1[[#This Row],[MoV]]-AVERAGE(Table1[MoV]))/STDEV(Table1[MoV]),(Table1[[#This Row],[MoD]]-AVERAGE(Table1[MoD]))/STDEV(Table1[MoD]),-(Table1[[#This Row],[Opp Prop]]-AVERAGE(Table1[Opp Prop]))/STDEV(Table1[Opp Prop])) -> -0.17664747 | AC13: =AVERAGE((Table1[[#This Row],[Coaching Efficiency]]-AVERAGE(Table1[Coaching Efficiency]))/STDEV(Table1[Coaching Efficiency]),(Table1[[#This Row],[Undrafted Points]]-AVERAGE(Table1[Undrafted Points]))/STDEV(Table1[Undrafted Points]),(Table1[[#This Row],[Projection_Starters]]-AVERAGE(Table1[Projection_Starters]))/STDEV(Table1[Projection_Starters])) -> -0.51546901
A14: Juwan's Big Johnson | B14: 1 | C14: {=SUMIFS([0]!Ideal_Points,[0]!Team_Total,'Team Summaries'!A14,[0]!Week_Total,'Team Summaries'!B14)} -> 145.06 | D14: {=SUMIFS([0]!Actual_Points,[0]!Team_Total,'Team Summaries'!A14,[0]!Week_Total,'Team Summaries'!B14)} -> 144.16 | E14: {=SUMIFS([0]!Missed_Points,[0]!Team_Total,'Team Summaries'!A14,[0]!Week_Total,'Team Summaries'!B14)} -> 0.9 | F14: {=10-SUMIFS([0]!Non_Drafted_Player,[0]!Team_Total,'Team Summaries'!A14,[0]!Week_Total,'Team Summaries'!B14)} -> 0 | G14: {=SUMIFS([0]!ND_Starter_Points,[0]!Team_Total,'Team Summaries'!A14,[0]!Week_Total,'Team Summaries'!B14)} -> 0 | I14: =I13+1 -> 12 | J14: pretty good team | K14: =AVERAGEIF($A$2:$A$1000,J14,$C$2:$C$1000) -> 99.18 | L14: =AVERAGEIF($A$2:$A$1000,Table1[[#This Row],[Team]],$D$2:$D$1000) -> 91.313333 | M14: =AVERAGEIF($A$2:$A$1000,Table1[[#This Row],[Team]],$E$2:$E$1000) -> 7.8666667 | N14: =Table1[[#This Row],[Actual Points]]/Table1[[#This Row],[Possible Points]] -> 0.92068293 | O14: =AVERAGEIF($A$2:$A$1000,Table1[[#This Row],[Team]],$F$2:$F$1000) -> 0.66666667 | P14: =AVERAGEIF($A$2:$A$1000,Table1[[#This Row],[Team]],$G$2:$G$1000) -> 0.33333333 | Q14: =_xlfn.XLOOKUP(Table1[[#This Row],[Team]],'Draft Recap'!$S$2:$S$15,'Draft Recap'!T$2:T$15) -> 2483 | R14: 1800 | S14: =_xlfn.XLOOKUP(Table1[[#This Row],[Team]],'Draft Recap'!$S$2:$S$15,'Draft Recap'!U$2:U$15) -> 341.38 | T14: =_xlfn.XLOOKUP(Table1[[#This Row],[Team]],'Draft Recap'!$S$2:$S$15,'Draft Recap'!V$2:V$15) -> 0 | U14: =_xlfn.XLOOKUP(Table1[[#This Row],[Team]],'Draft Recap'!$S$2:$S$15,'Draft Recap'!W$2:W$15) -> 1934.4867 | V14: =_xlfn.XLOOKUP(Table1[[#This Row],[Team]],'Draft Recap'!$S$2:$S$15,'Draft Recap'!X$2:X$15) -> -548.51333 | W14: =_xlfn.XLOOKUP(Table1[[#This Row],[Team]],'Draft Recap'!$S$2:$S$15,'Draft Recap'!Y$2:Y$15) -> 3 | X14: =_xlfn.XLOOKUP(Table1[[#This Row],[Team]],'Draft Recap'!$S$2:$S$15,'Draft Recap'!Z$2:Z$15) -> 3.75 | Y14: =_xlfn.XLOOKUP(Table1[[#This Row],[Team]],'Draft Recap'!$S$2:$S$15,'Draft Recap'!AA$2:AA$15) -> 0 | Z14: =_xlfn.XLOOKUP(Table1[[#This Row],[Team]],'Draft Recap'!$S$2:$S$15,'Draft Recap'!AB$2:AB$15) -> 34.92 | AA14: =_xlfn.XLOOKUP(Table1[[#This Row],[Team]],'Draft Recap'!$S$2:$S$15,'Draft Recap'!AC$2:AC$15) -> 1.0472273 | AB14: =AVERAGE((Table1[[#This Row],[Dif]]-AVERAGE(Table1[Dif]))/STDEV(Table1[Dif]),-(Table1[[#This Row],[Weighted INJ]]-AVERAGE(Table1[Weighted INJ]))/STDEV(Table1[Weighted INJ]),-(Table1[[#This Row],[MoV]]-AVERAGE(Table1[MoV]))/STDEV(Table1[MoV]),(Table1[[#This Row],[MoD]]-AVERAGE(Table1[MoD]))/STDEV(Table1[MoD]),-(Table1[[#This Row],[Opp Prop]]-AVERAGE(Table1[Opp Prop]))/STDEV(Table1[Opp Prop])) -> 0.15424588 | AC14: =AVERAGE((Table1[[#This Row],[Coaching Efficiency]]-AVERAGE(Table1[Coaching Efficiency]))/STDEV(Table1[Coaching Efficiency]),(Table1[[#This Row],[Undrafted Points]]-AVERAGE(Table1[Undrafted Points]))/STDEV(Table1[Undrafted Points]),(Table1[[#This Row],[Projection_Starters]]-AVERAGE(Table1[Projection_Starters]))/STDEV(Table1[Projection_Starters])) -> -0.6901502
A15: Jungle Drummer | B15: 1 | C15: {=SUMIFS([0]!Ideal_Points,[0]!Team_Total,'Team Summaries'!A15,[0]!Week_Total,'Team Summaries'!B15)} -> 101.12 | D15: {=SUMIFS([0]!Actual_Points,[0]!Team_Total,'Team Summaries'!A15,[0]!Week_Total,'Team Summaries'!B15)} -> 90.82 | E15: {=SUMIFS([0]!Missed_Points,[0]!Team_Total,'Team Summaries'!A15,[0]!Week_Total,'Team Summaries'!B15)} -> 10.3 | F15: {=10-SUMIFS([0]!Non_Drafted_Player,[0]!Team_Total,'Team Summaries'!A15,[0]!Week_Total,'Team Summaries'!B15)} -> 1 | G15: {=SUMIFS([0]!ND_Starter_Points,[0]!Team_Total,'Team Summaries'!A15,[0]!Week_Total,'Team Summaries'!B15)} -> 3.7 | I15: =I14+1 -> 13 | J15: Juwan's Big Johnson | K15: =AVERAGEIF($A$2:$A$1000,J15,$C$2:$C$1000) -> 129.46 | L15: =AVERAGEIF($A$2:$A$1000,Table1[[#This Row],[Team]],$D$2:$D$1000) -> 118.00667 | M15: =AVERAGEIF($A$2:$A$1000,Table1[[#This Row],[Team]],$E$2:$E$1000) -> 11.453333 | N15: =Table1[[#This Row],[Actual Points]]/Table1[[#This Row],[Possible Points]] -> 0.91152994 | O15: =AVERAGEIF($A$2:$A$1000,Table1[[#This Row],[Team]],$F$2:$F$1000) -> 1 | P15: =AVERAGEIF($A$2:$A$1000,Table1[[#This Row],[Team]],$G$2:$G$1000) -> 13.513333 | Q15: =_xlfn.XLOOKUP(Table1[[#This Row],[Team]],'Draft Recap'!$S$2:$S$15,'Draft Recap'!T$2:T$15) -> 2360 | R15: 1791 | S15: =_xlfn.XLOOKUP(Table1[[#This Row],[Team]],'Draft Recap'!$S$2:$S$15,'Draft Recap'!U$2:U$15) -> 405.48 | T15: =_xlfn.XLOOKUP(Table1[[#This Row],[Team]],'Draft Recap'!$S$2:$S$15,'Draft Recap'!V$2:V$15) -> 0 | U15: =_xlfn.XLOOKUP(Table1[[#This Row],[Team]],'Draft Recap'!$S$2:$S$15,'Draft Recap'!W$2:W$15) -> 2297.72 | V15: =_xlfn.XLOOKUP(Table1[[#This Row],[Team]],'Draft Recap'!$S$2:$S$15,'Draft Recap'!X$2:X$15) -> -62.28 | W15: =_xlfn.XLOOKUP(Table1[[#This Row],[Team]],'Draft Recap'!$S$2:$S$15,'Draft Recap'!Y$2:Y$15) -> 3 | X15: =_xlfn.XLOOKUP(Table1[[#This Row],[Team]],'Draft Recap'!$S$2:$S$15,'Draft Recap'!Z$2:Z$15) -> 9 | Y15: =_xlfn.XLOOKUP(Table1[[#This Row],[Team]],'Draft Recap'!$S$2:$S$15,'Draft Recap'!AA$2:AA$15) -> 40.05 | Z15: =_xlfn.XLOOKUP(Table1[[#This Row],[Team]],'Draft Recap'!$S$2:$S$15,'Draft Recap'!AB$2:AB$15) -> 24.3 | AA15: =_xlfn.XLOOKUP(Table1[[#This Row],[Team]],'Draft Recap'!$S$2:$S$15,'Draft Recap'!AC$2:AC$15) -> 1 | AB15: =AVERAGE((Table1[[#This Row],[Dif]]-AVERAGE(Table1[Dif]))/STDEV(Table1[Dif]),-(Table1[[#This Row],[Weighted INJ]]-AVERAGE(Table1[Weighted INJ]))/STDEV(Table1[Weighted INJ]),-(Table1[[#This Row],[MoV]]-AVERAGE(Table1[MoV]))/STDEV(Table1[MoV]),(Table1[[#This Row],[MoD]]-AVERAGE(Table1[MoD]))/STDEV(Table1[MoD]),-(Table1[[#This Row],[Opp Prop]]-AVERAGE(Table1[Opp Prop]))/STDEV(Table1[Opp Prop])) -> -0.29429207 | AC15: =AVERAGE((Table1[[#This Row],[Coaching Efficiency]]-AVERAGE(Table1[Coaching Efficiency]))/STDEV(Table1[Coaching Efficiency]),(Table1[[#This Row],[Undrafted Points]]-AVERAGE(Table1[Undrafted Points]))/STDEV(Table1[Undrafted Points]),(Table1[[#This Row],[Projection_Starters]]-AVERAGE(Table1[Projection_Starters]))/STDEV(Table1[Projection_Starters])) -> -0.052472455
A16: Coach Carlt | B16: 2 | C16: {=SUMIFS([0]!Ideal_Points,[0]!Team_Total,'Team Summaries'!A16,[0]!Week_Total,'Team Summaries'!B16)} -> 108.22 | D16: {=SUMIFS([0]!Actual_Points,[0]!Team_Total,'Team Summaries'!A16,[0]!Week_Total,'Team Summaries'!B16)} -> 102.04 | E16: {=SUMIFS([0]!Missed_Points,[0]!Team_Total,'Team Summaries'!A16,[0]!Week_Total,'Team Summaries'!B16)} -> 6.18 | F16: {=10-SUMIFS([0]!Non_Drafted_Player,[0]!Team_Total,'Team Summaries'!A16,[0]!Week_Total,'Team Summaries'!B16)} -> 0 | G16: {=SUMIFS([0]!ND_Starter_Points,[0]!Team_Total,'Team Summaries'!A16,[0]!Week_Total,'Team Summaries'!B16)} -> 0 | I16: =I15+1 -> 14 | J16: Jungle Drummer | K16: =AVERAGEIF($A$2:$A$1000,J16,$C$2:$C$1000) -> 118.44 | L16: =AVERAGEIF($A$2:$A$1000,Table1[[#This Row],[Team]],$D$2:$D$1000) -> 104.53333 | M16: =AVERAGEIF($A$2:$A$1000,Table1[[#This Row],[Team]],$E$2:$E$1000) -> 13.906667 | N16: =Table1[[#This Row],[Actual Points]]/Table1[[#This Row],[Possible Points]] -> 0.88258471 | O16: =AVERAGEIF($A$2:$A$1000,Table1[[#This Row],[Team]],$F$2:$F$1000) -> 1.3333333 | P16: =AVERAGEIF($A$2:$A$1000,Table1[[#This Row],[Team]],$G$2:$G$1000) -> 7.3333333 | Q16: =_xlfn.XLOOKUP(Table1[[#This Row],[Team]],'Draft Recap'!$S$2:$S$15,'Draft Recap'!T$2:T$15) -> 2408 | R16: 1871 | S16: =_xlfn.XLOOKUP(Table1[[#This Row],[Team]],'Draft Recap'!$S$2:$S$15,'Draft Recap'!U$2:U$15) -> 400.88 | T16: =_xlfn.XLOOKUP(Table1[[#This Row],[Team]],'Draft Recap'!$S$2:$S$15,'Draft Recap'!V$2:V$15) -> 0 | U16: =_xlfn.XLOOKUP(Table1[[#This Row],[Team]],'Draft Recap'!$S$2:$S$15,'Draft Recap'!W$2:W$15) -> 2271.6533 | V16: =_xlfn.XLOOKUP(Table1[[#This Row],[Team]],'Draft Recap'!$S$2:$S$15,'Draft Recap'!X$2:X$15) -> -136.34667 | W16: =_xlfn.XLOOKUP(Table1[[#This Row],[Team]],'Draft Recap'!$S$2:$S$15,'Draft Recap'!Y$2:Y$15) -> 0 | X16: =_xlfn.XLOOKUP(Table1[[#This Row],[Team]],'Draft Recap'!$S$2:$S$15,'Draft Recap'!Z$2:Z$15) -> 0 | Y16: =_xlfn.XLOOKUP(Table1[[#This Row],[Team]],'Draft Recap'!$S$2:$S$15,'Draft Recap'!AA$2:AA$15) -> 0 | Z16: =_xlfn.XLOOKUP(Table1[[#This Row],[Team]],'Draft Recap'!$S$2:$S$15,'Draft Recap'!AB$2:AB$15) -> 30.886667 | AA16: =_xlfn.XLOOKUP(Table1[[#This Row],[Team]],'Draft Recap'!$S$2:$S$15,'Draft Recap'!AC$2:AC$15) -> 1.0489965 | AB16: =AVERAGE((Table1[[#This Row],[Dif]]-AVERAGE(Table1[Dif]))/STDEV(Table1[Dif]),-(Table1[[#This Row],[Weighted INJ]]-AVERAGE(Table1[Weighted INJ]))/STDEV(Table1[Weighted INJ]),-(Table1[[#This Row],[MoV]]-AVERAGE(Table1[MoV]))/STDEV(Table1[MoV]),(Table1[[#This Row],[MoD]]-AVERAGE(Table1[MoD]))/STDEV(Table1[MoD]),-(Table1[[#This Row],[Opp Prop]]-AVERAGE(Table1[Opp Prop]))/STDEV(Table1[Opp Prop])) -> 0.63186679 | AC16: =AVERAGE((Table1[[#This Row],[Coaching Efficiency]]-AVERAGE(Table1[Coaching Efficiency]))/STDEV(Table1[Coaching Efficiency]),(Table1[[#This Row],[Undrafted Points]]-AVERAGE(Table1[Undrafted Points]))/STDEV(Table1[Undrafted Points]),(Table1[[#This Row],[Projection_Starters]]-AVERAGE(Table1[Projection_Starters]))/STDEV(Table1[Projection_Starters])) -> 0.076465218
A17: Picken Dis Nose | B17: 2 | C17: {=SUMIFS([0]!Ideal_Points,[0]!Team_Total,'Team Summaries'!A17,[0]!Week_Total,'Team Summaries'!B17)} -> 133.38 | D17: {=SUMIFS([0]!Actual_Points,[0]!Team_Total,'Team Summaries'!A17,[0]!Week_Total,'Team Summaries'!B17)} -> 120.88 | E17: {=SUMIFS([0]!Missed_Points,[0]!Team_Total,'Team Summaries'!A17,[0]!Week_Total,'Team Summaries'!B17)} -> 12.5 | F17: {=10-SUMIFS([0]!Non_Drafted_Player,[0]!Team_Total,'Team Summaries'!A17,[0]!Week_Total,'Team Summaries'!B17)} -> 3 | G17: {=SUMIFS([0]!ND_Starter_Points,[0]!Team_Total,'Team Summaries'!A17,[0]!Week_Total,'Team Summaries'!B17)} -> 17.8
A18: The Strib Club | B18: 2 | C18: {=SUMIFS([0]!Ideal_Points,[0]!Team_Total,'Team Summaries'!A18,[0]!Week_Total,'Team Summaries'!B18)} -> 127.22 | D18: {=SUMIFS([0]!Actual_Points,[0]!Team_Total,'Team Summaries'!A18,[0]!Week_Total,'Team Summaries'!B18)} -> 110.82 | E18: {=SUMIFS([0]!Missed_Points,[0]!Team_Total,'Team Summaries'!A18,[0]!Week_Total,'Team Summaries'!B18)} -> 16.4 | F18: {=10-SUMIFS([0]!Non_Drafted_Player,[0]!Team_Total,'Team Summaries'!A18,[0]!Week_Total,'Team Summaries'!B18)} -> 1 | G18: {=SUMIFS([0]!ND_Starter_Points,[0]!Team_Total,'Team Summaries'!A18,[0]!Week_Total,'Team Summaries'!B18)} -> 4.9
A19: Shough and pray | B19: 2 | C19: {=SUMIFS([0]!Ideal_Points,[0]!Team_Total,'Team Summaries'!A19,[0]!Week_Total,'Team Summaries'!B19)} -> 135.18 | D19: {=SUMIFS([0]!Actual_Points,[0]!Team_Total,'Team Summaries'!A19,[0]!Week_Total,'Team Summaries'!B19)} -> 135.18 | E19: {=SUMIFS([0]!Missed_Points,[0]!Team_Total,'Team Summaries'!A19,[0]!Week_Total,'Team Summaries'!B19)} -> -4.4408921e-16 | F19: {=10-SUMIFS([0]!Non_Drafted_Player,[0]!Team_Total,'Team Summaries'!A19,[0]!Week_Total,'Team Summaries'!B19)} -> 2 | G19: {=SUMIFS([0]!ND_Starter_Points,[0]!Team_Total,'Team Summaries'!A19,[0]!Week_Total,'Team Summaries'!B19)} -> 27.2
A20: Pleading the Fifth Down | B20: 2 | C20: {=SUMIFS([0]!Ideal_Points,[0]!Team_Total,'Team Summaries'!A20,[0]!Week_Total,'Team Summaries'!B20)} -> 122.62 | D20: {=SUMIFS([0]!Actual_Points,[0]!Team_Total,'Team Summaries'!A20,[0]!Week_Total,'Team Summaries'!B20)} -> 110.52 | E20: {=SUMIFS([0]!Missed_Points,[0]!Team_Total,'Team Summaries'!A20,[0]!Week_Total,'Team Summaries'!B20)} -> 12.1 | F20: {=10-SUMIFS([0]!Non_Drafted_Player,[0]!Team_Total,'Team Summaries'!A20,[0]!Week_Total,'Team Summaries'!B20)} -> 0 | G20: {=SUMIFS([0]!ND_Starter_Points,[0]!Team_Total,'Team Summaries'!A20,[0]!Week_Total,'Team Summaries'!B20)} -> 0
A21: Please Let Me Win IDK what 2 do | B21: 2 | C21: {=SUMIFS([0]!Ideal_Points,[0]!Team_Total,'Team Summaries'!A21,[0]!Week_Total,'Team Summaries'!B21)} -> 126.5 | D21: {=SUMIFS([0]!Actual_Points,[0]!Team_Total,'Team Summaries'!A21,[0]!Week_Total,'Team Summaries'!B21)} -> 113.1 | E21: {=SUMIFS([0]!Missed_Points,[0]!Team_Total,'Team Summaries'!A21,[0]!Week_Total,'Team Summaries'!B21)} -> 13.4 | F21: {=10-SUMIFS([0]!Non_Drafted_Player,[0]!Team_Total,'Team Summaries'!A21,[0]!Week_Total,'Team Summaries'!B21)} -> 0 | G21: {=SUMIFS([0]!ND_Starter_Points,[0]!Team_Total,'Team Summaries'!A21,[0]!Week_Total,'Team Summaries'!B21)} -> 0
A22: I'm At My Limit | B22: 2 | C22: {=SUMIFS([0]!Ideal_Points,[0]!Team_Total,'Team Summaries'!A22,[0]!Week_Total,'Team Summaries'!B22)} -> 112.68 | D22: {=SUMIFS([0]!Actual_Points,[0]!Team_Total,'Team Summaries'!A22,[0]!Week_Total,'Team Summaries'!B22)} -> 95.78 | E22: {=SUMIFS([0]!Missed_Points,[0]!Team_Total,'Team Summaries'!A22,[0]!Week_Total,'Team Summaries'!B22)} -> 16.9 | F22: {=10-SUMIFS([0]!Non_Drafted_Player,[0]!Team_Total,'Team Summaries'!A22,[0]!Week_Total,'Team Summaries'!B22)} -> 1 | G22: {=SUMIFS([0]!ND_Starter_Points,[0]!Team_Total,'Team Summaries'!A22,[0]!Week_Total,'Team Summaries'!B22)} -> 10
A23: Puka bit my finger | B23: 2 | C23: {=SUMIFS([0]!Ideal_Points,[0]!Team_Total,'Team Summaries'!A23,[0]!Week_Total,'Team Summaries'!B23)} -> 99.98 | D23: {=SUMIFS([0]!Actual_Points,[0]!Team_Total,'Team Summaries'!A23,[0]!Week_Total,'Team Summaries'!B23)} -> 79.58 | E23: {=SUMIFS([0]!Missed_Points,[0]!Team_Total,'Team Summaries'!A23,[0]!Week_Total,'Team Summaries'!B23)} -> 20.4 | F23: {=10-SUMIFS([0]!Non_Drafted_Player,[0]!Team_Total,'Team Summaries'!A23,[0]!Week_Total,'Team Summaries'!B23)} -> 0 | G23: {=SUMIFS([0]!ND_Starter_Points,[0]!Team_Total,'Team Summaries'!A23,[0]!Week_Total,'Team Summaries'!B23)} -> 0
A24: Lemieuse-bouche sais quoi | B24: 2 | C24: {=SUMIFS([0]!Ideal_Points,[0]!Team_Total,'Team Summaries'!A24,[0]!Week_Total,'Team Summaries'!B24)} -> 123.92 | D24: {=SUMIFS([0]!Actual_Points,[0]!Team_Total,'Team Summaries'!A24,[0]!Week_Total,'Team Summaries'!B24)} -> 116.92 | E24: {=SUMIFS([0]!Missed_Points,[0]!Team_Total,'Team Summaries'!A24,[0]!Week_Total,'Team Summaries'!B24)} -> 7 | F24: {=10-SUMIFS([0]!Non_Drafted_Player,[0]!Team_Total,'Team Summaries'!A24,[0]!Week_Total,'Team Summaries'!B24)} -> 0 | G24: {=SUMIFS([0]!ND_Starter_Points,[0]!Team_Total,'Team Summaries'!A24,[0]!Week_Total,'Team Summaries'!B24)} -> 0
A25: the medical tent apparently | B25: 2 | C25: {=SUMIFS([0]!Ideal_Points,[0]!Team_Total,'Team Summaries'!A25,[0]!Week_Total,'Team Summaries'!B25)} -> 120.26 | D25: {=SUMIFS([0]!Actual_Points,[0]!Team_Total,'Team Summaries'!A25,[0]!Week_Total,'Team Summaries'!B25)} -> 92.3 | E25: {=SUMIFS([0]!Missed_Points,[0]!Team_Total,'Team Summaries'!A25,[0]!Week_Total,'Team Summaries'!B25)} -> 27.96 | F25: {=10-SUMIFS([0]!Non_Drafted_Player,[0]!Team_Total,'Team Summaries'!A25,[0]!Week_Total,'Team Summaries'!B25)} -> 0 | G25: {=SUMIFS([0]!ND_Starter_Points,[0]!Team_Total,'Team Summaries'!A25,[0]!Week_Total,'Team Summaries'!B25)} -> 0
A26: your friendly fantasy despot | B26: 2 | C26: {=SUMIFS([0]!Ideal_Points,[0]!Team_Total,'Team Summaries'!A26,[0]!Week_Total,'Team Summaries'!B26)} -> 131.28 | D26: {=SUMIFS([0]!Actual_Points,[0]!Team_Total,'Team Summaries'!A26,[0]!Week_Total,'Team Summaries'!B26)} -> 131.28 | E26: {=SUMIFS([0]!Missed_Points,[0]!Team_Total,'Team Summaries'!A26,[0]!Week_Total,'Team Summaries'!B26)} -> 0 | F26: {=10-SUMIFS([0]!Non_Drafted_Player,[0]!Team_Total,'Team Summaries'!A26,[0]!Week_Total,'Team Summaries'!B26)} -> 0 | G26: {=SUMIFS([0]!ND_Starter_Points,[0]!Team_Total,'Team Summaries'!A26,[0]!Week_Total,'Team Summaries'!B26)} -> 0
A27: pretty good team | B27: 2 | C27: {=SUMIFS([0]!Ideal_Points,[0]!Team_Total,'Team Summaries'!A27,[0]!Week_Total,'Team Summaries'!B27)} -> 59.16 | D27: {=SUMIFS([0]!Actual_Points,[0]!Team_Total,'Team Summaries'!A27,[0]!Week_Total,'Team Summaries'!B27)} -> 56.16 | E27: {=SUMIFS([0]!Missed_Points,[0]!Team_Total,'Team Summaries'!A27,[0]!Week_Total,'Team Summaries'!B27)} -> 3 | F27: {=10-SUMIFS([0]!Non_Drafted_Player,[0]!Team_Total,'Team Summaries'!A27,[0]!Week_Total,'Team Summaries'!B27)} -> 1 | G27: {=SUMIFS([0]!ND_Starter_Points,[0]!Team_Total,'Team Summaries'!A27,[0]!Week_Total,'Team Summaries'!B27)} -> 7
A28: Juwan's Big Johnson | B28: 2 | C28: {=SUMIFS([0]!Ideal_Points,[0]!Team_Total,'Team Summaries'!A28,[0]!Week_Total,'Team Summaries'!B28)} -> 101.98 | D28: {=SUMIFS([0]!Actual_Points,[0]!Team_Total,'Team Summaries'!A28,[0]!Week_Total,'Team Summaries'!B28)} -> 92.62 | E28: {=SUMIFS([0]!Missed_Points,[0]!Team_Total,'Team Summaries'!A28,[0]!Week_Total,'Team Summaries'!B28)} -> 9.36 | F28: {=10-SUMIFS([0]!Non_Drafted_Player,[0]!Team_Total,'Team Summaries'!A28,[0]!Week_Total,'Team Summaries'!B28)} -> 1 | G28: {=SUMIFS([0]!ND_Starter_Points,[0]!Team_Total,'Team Summaries'!A28,[0]!Week_Total,'Team Summaries'!B28)} -> 2.8
... A43: Jungle Drummer | B43: 3 | C43: {=SUMIFS([0]!Ideal_Points,[0]!Team_Total,'Team Summaries'!A43,[0]!Week_Total,'Team Summaries'!B43)} -> 123.84 | D43: {=SUMIFS([0]!Actual_Points,[0]!Team_Total,'Team Summaries'!A43,[0]!Week_Total,'Team Summaries'!B43)} -> 114.72 | E43: {=SUMIFS([0]!Missed_Points,[0]!Team_Total,'Team Summaries'!A43,[0]!Week_Total,'Team Summaries'!B43)} -> 9.12 | F43: {=10-SUMIFS([0]!Non_Drafted_Player,[0]!Team_Total,'Team Summaries'!A43,[0]!Week_Total,'Team Summaries'!B43)} -> 3 | G43: {=SUMIFS([0]!ND_Starter_Points,[0]!Team_Total,'Team Summaries'!A43,[0]!Week_Total,'Team Summaries'!B43)} -> 18.3

Sheet Summary
A1: Team | B1: Possible Points | C1: Actual Points | D1: Points Missed | E1: Coaching Efficiency | F1: Undrafted Players | G1: Undrafted Points | H1: Projection | I1: Projection_Starters | J1: Actual | K1: Byes | L1: Paced | M1: Dif | N1: INJ | O1: Weighted INJ | P1: MoV | Q1: MoD | R1: Opp Prop | S1: Luck Rating | T1: Manager Rating
A2: ='Team Summaries'!J3 -> Coach Carlt | B2: ='Team Summaries'!K3 -> 110.15333 | C2: ='Team Summaries'!L3 -> 107.82667 | D2: ='Team Summaries'!M3 -> 2.3266667 | E2: ='Team Summaries'!N3 -> 0.97887793 | F2: ='Team Summaries'!O3 -> 0 | G2: ='Team Summaries'!P3 -> 0 | H2: ='Team Summaries'!Q3 -> 2480 | ... T2: ='Team Summaries'!AC3 -> 0.27953576
A3: ='Team Summaries'!J4 -> Picken Dis Nose | B3: ='Team Summaries'!K4 -> 113.05333 | C3: ='Team Summaries'!L4 -> 98.053333 | D3: ='Team Summaries'!M4 -> 15 | E3: ='Team Summaries'!N4 -> 0.86731926 | F3: ='Team Summaries'!O4 -> 2.3333333 | G3: ='Team Summaries'!P4 -> 12.666667 | H3: ='Team Summaries'!Q4 -> 2339 | ... T3: ='Team Summaries'!AC4 -> 0.0045102441
A4: ='Team Summaries'!J5 -> The Strib Club | B4: ='Team Summaries'!K5 -> 108.74667 | C4: ='Team Summaries'!L5 -> 93.113333 | D4: ='Team Summaries'!M5 -> 15.633333 | E4: ='Team Summaries'!N5 -> 0.8562408 | F4: ='Team Summaries'!O5 -> 1 | G4: ='Team Summaries'!P5 -> 5.4333333 | H4: ='Team Summaries'!Q5 -> 2163 | ... T4: ='Team Summaries'!AC5 -> -0.78267519
A5: ='Team Summaries'!J6 -> Shough and pray | B5: ='Team Summaries'!K6 -> 143.89333 | C5: ='Team Summaries'!L6 -> 139.06 | D5: ='Team Summaries'!M6 -> 4.8333333 | E5: ='Team Summaries'!N6 -> 0.9664103 | F5: ='Team Summaries'!O6 -> 1.3333333 | G5: ='Team Summaries'!P6 -> 14.533333 | H5: ='Team Summaries'!Q6 -> 2227 | ... T5: ='Team Summaries'!AC6 -> 1.2190052
A6: ='Team Summaries'!J7 -> Pleading the Fifth Down | B6: ='Team Summaries'!K7 -> 135.36667 | C6: ='Team Summaries'!L7 -> 119.86667 | D6: ='Team Summaries'!M7 -> 15.5 | E6: ='Team Summaries'!N7 -> 0.88549618 | F6: ='Team Summaries'!O7 -> 0.33333333 | G6: ='Team Summaries'!P7 -> 4.5466667 | H6: ='Team Summaries'!Q7 -> 2558 | ... T6: ='Team Summaries'!AC7 -> 0.22068711
A7: ='Team Summaries'!J8 -> Please Let Me Win IDK what 2 do | B7: ='Team Summaries'!K8 -> 140.96 | C7: ='Team Summaries'!L8 -> 136.39333 | D7: ='Team Summaries'!M8 -> 4.5666667 | E7: ='Team Summaries'!N8 -> 0.9676031 | F7: ='Team Summaries'!O8 -> 0.33333333 | G7: ='Team Summaries'!P8 -> 7.4066667 | H7: ='Team Summaries'!Q8 -> 2178 | ... T7: ='Team Summaries'!AC8 -> 0.77002374
A8: ='Team Summaries'!J9 -> I'm At My Limit | B8: ='Team Summaries'!K9 -> 124.28 | C8: ='Team Summaries'!L9 -> 110.16 | D8: ='Team Summaries'!M9 -> 14.12 | E8: ='Team Summaries'!N9 -> 0.88638558 | F8: ='Team Summaries'!O9 -> 1.3333333 | G8: ='Team Summaries'!P9 -> 13.333333 | H8: ='Team Summaries'!Q9 -> 2425 | ... T8: ='Team Summaries'!AC9 -> 0.48525626
A9: ='Team Summaries'!J10 -> Puka bit my finger | B9: ='Team Summaries'!K10 -> 115.66667 | C9: ='Team Summaries'!L10 -> 96.473333 | D9: ='Team Summaries'!M10 -> 19.193333 | E9: ='Team Summaries'!N10 -> 0.8340634 | F9: ='Team Summaries'!O10 -> 0 | G9: ='Team Summaries'!P10 -> 0 | H9: ='Team Summaries'!Q10 -> 2523 | ... T9: ='Team Summaries'!AC10 -> -0.66659724
